<?xml version="1.0"?>
<robot name = "robot_arm">


<!-- Dummy link to address KDL warning -->
<link name="dummy_link">
    <inertial>
        <mass value="1e-5"/>
        <inertia ixx="1e-10" ixy="0" ixz="0" iyy="1e-10" iyz="0" izz="1e-10"/>
    </inertial>
</link>

<joint name="fixed_joint" type="fixed">
    <parent link="dummy_link"/>
    <child link="base_link"/>
</joint>



<!-- base link -->
<link name = "base_link">
    <visual>
    <geometry>
	  <mesh filename="package://Project64/meshes/bese_link.STL" scale="1.5 1.5 1.5"/>

        
    </geometry>
    <origin xyz="0 280 355" rpy="1.67 2.25 0.07"/>
    </visual>

    <collision>
        <geometry>
		    <mesh filename="package://Project64/meshes/bese_link.STL" scale="1.5 1.5 1.5"/>

           
        </geometry>
        <origin xyz="0 0 0" rpy="0 0 0"/>
    </collision>

    <inertial>
        <origin xyz="0 0 0" rpy="0 0 0"/>
        <mass value="1"/>
        <inertia ixx="0.001" ixy="0" ixz= "0" iyy="0.001" iyz="0" izz="0.001"/>
    </inertial>
</link>

<!-- link 1 -->
<link name = "link1">
    <visual>
    <geometry>
	  <mesh filename="package://Project64/meshes/link.STL" scale="1.5 1.5 1.5"/>

        <!--cylinder length="0.1" radius="0.1"/--> 
    </geometry>
    <origin xyz="100 -100 15" rpy="0 0 1.55"/>
    <material name= "black">
        <color rgba="0 0 0 1"/>
    </material>
    </visual>

    <collision>
        <geometry>
		    <mesh filename="package://Project64/meshes/link.STL" scale="1.5 1.5 1.5"/>

            <!-- <cylinder length="0.1" radius="0.1"/>  -->
        </geometry>
        <origin xyz="0 0 0" rpy="0 0 0"/>
    </collision>

    <inertial>
        <origin xyz="0 0 0" rpy="0 0 0"/>
        <mass value="1"/>
        <inertia ixx="0.001" ixy="0" ixz= "0" iyy="0.001" iyz="0" izz="0.001"/>
    </inertial>
</link>

<!--joint1-->
<joint name="joint1" type="prismatic">
    <parent link="base_link"/>
    <child link="link1"/>
    <origin xyz="0 0 0.1" rpy="0 0 0"/>
    <axis xyz="0 1 0 " />
    <limit lower="-82.5" upper="82.5" effort="100" velocity="1"/>
</joint>
<!--link2-->
<link name = "link2">
    <visual>
    <geometry>
	  <mesh filename="package://Project64/meshes/link2.STL" scale="1.5 1.5 1.5"/>

        <!--cylinder length="0.1" radius="0.1"/--> 
    </geometry>
    <origin xyz="-110 -25 70" rpy="0 0 0"/>
    </visual>

    <collision>
        <geometry>
		    <mesh filename="package://Project64/meshes/link2.STL" scale="1.5 1.5 1.5"/>

            <!-- <cylinder length="0.1" radius="0.1"/>  -->
        </geometry>
        <origin xyz="0 0 0" rpy="0 0 0"/>
    </collision>

    <inertial>
        <origin xyz="0 0 0" rpy="0 0 0"/>
        <mass value="1"/>
        <inertia ixx="0.001" ixy="0" ixz= "0" iyy="0.001" iyz="0" izz="0.001"/>
    </inertial>
</link>
<!--joint2-->
<joint name="joint2" type="prismatic">
    <parent link="link1"/>
    <child link="link2"/>
    <origin xyz="0 0 0.1" rpy="0 0 0"/>
    <axis xyz="1 0 0 " />
    <limit lower="-55.0" upper="55.0" effort="100" velocity="1"/>
</joint>


</robot>
